<?xml version="1.0" encoding="utf-8"?>
<!-- This URDF was automatically created by SolidWorks to URDF Exporter! Originally created by Stephen Brawner (brawner@gmail.com) 
     Commit Version: 1.6.0-4-g7f85cfe  Build Version: 1.6.7995.38578
     For more information, please see http://wiki.ros.org/sw_urdf_exporter -->
<robot
  name="wow002">
  <link
    name="pelvis">

    <inertial>
      <origin
        xyz="-0.06455164 7.184e-05 -0.03678152"
        rpy="0 0 0" />
      <mass
        value="2.6836579" />
      <inertia
        ixx="0.01366036"
        ixy="4.02e-06"
        ixz="-0.00096822"
        iyy="0.00468233"
        iyz="-4.99e-06"
        izz="0.01556904" />
    </inertial>

    <visual>
      <origin
        xyz="0 0 0"
        rpy="0 0 0" />
      <geometry>
        <mesh
          filename="../meshes/pelvis.STL" />
      </geometry>
      <material
        name="">
        <color
          rgba="0.79216 0.81961 0.93333 1" />
      </material>
    </visual>
    <collision>
      <origin
        xyz="-0.08 0 0"
        rpy="0 0 0" />
      <geometry>
        <box size="0.055 0.26 0.11"/>
      </geometry>
    </collision>
  </link>
  <link
    name="left_hip_roll_link">
    <inertial>
      <origin
        xyz="0.06091912 0.00137016 0.0006284"
        rpy="0 0 0" />
      <mass
        value="1.03840785" />
      <inertia
        ixx="0.00029429"
        ixy="1.032e-05"
        ixz="-2.24e-06"
        iyy="0.00037781"
        iyz="7.3e-07"
        izz="0.00050007" />
    </inertial>

    <visual>
      <origin
        xyz="0 0 0"
        rpy="0 0 0" />
      <geometry>
        <mesh
          filename="../meshes/left_hip_roll_link.STL" />
      </geometry>
      <material
        name="">
        <color
          rgba="1 1 1 1" />
      </material>
    </visual>
    <collision>
      <origin
        xyz="0 0 0"
        rpy="0 0 0" />
      <geometry>
        <mesh
          filename="../meshes/left_hip_roll_link.STL" />
      </geometry>
    </collision>
  </link>
  <joint
    name="left_hip_roll_joint"
    type="revolute">
    <origin
      xyz="-0.054784 0.075 -0.042"
      rpy="0 0 0" />
    <parent
      link="pelvis" />
    <child
      link="left_hip_roll_link" />
    <axis
      xyz="1 0 0" />
    <limit
      lower="-0.1"
      upper="1"
      effort="80"
      velocity="15" />
  </joint>
  <link
    name="left_hip_yaw_link">


    <inertial>
      <origin
        xyz="0.0 -0.01974414 -0.04022558"
        rpy="0 0 0" />
      <mass
        value="0.3035" />
      <inertia
        ixx="0.00045263"
        ixy="-0.0"
        ixz="-0.0"
        iyy="0.00045054"
        iyz="-9.874e-05"
        izz="0.00016735" />
    </inertial>
    <visual>
      <origin
        xyz="0 0 0"
        rpy="0 0 0" />
      <geometry>
        <mesh
          filename="../meshes/left_hip_yaw_link.STL" />
      </geometry>
      <material
        name="">
        <color
          rgba="0.66667 0.69804 0.76863 1" />
      </material>
    </visual>
    <!-- <collision>
      <origin
        xyz="0 0 0"
        rpy="0 0 0" />
      <geometry>
        <mesh
          filename="../meshes/left_hip_yaw_link.STL" />
      </geometry>
    </collision> -->
  </link>
  <joint
    name="left_hip_yaw_joint"
    type="revolute">
    <origin
      xyz="0.0648 0 -0.02725"
      rpy="0 0 0" />
    <parent
      link="left_hip_roll_link" />
    <child
      link="left_hip_yaw_link" />
    <axis
      xyz="0 0 1" />
    <limit
      lower="-0.7"
      upper="0.7"
      effort="90"
      velocity="15" />  
  </joint>
  <link
    name="left_hip_pitch_link">
    <inertial>
      <origin
        xyz="-0.0007288 0.00132281 -0.09181702"
        rpy="0 0 0" />
      <mass
        value="4.1691243" />
      <inertia
        ixx="0.03196599"
        ixy="-0.00010018"
        ixz="-0.00042031"
        iyy="0.03363389"
        iyz="-0.00064667"
        izz="0.0029827" />
    </inertial>
    <visual>
      <origin
        xyz="0 0 0"
        rpy="0 0 0" />
      <geometry>
        <mesh
          filename="../meshes/left_hip_pitch_link.STL" />
      </geometry>
      <material
        name="">
        <color
          rgba="0.98824 1 0.88235 1" />
      </material>
    </visual>
    <collision>
      <origin
        xyz="0 0 0"
        rpy="0 0 0" />
      <geometry>
        <mesh
          filename="../meshes/left_hip_pitch_link.STL" />
      </geometry>
    </collision>
  </link>
  <joint
    name="left_hip_pitch_joint"
    type="revolute">
    <origin
      xyz="0 0 -0.082"
      rpy="0 0 0" />
    <parent
      link="left_hip_yaw_link" />
    <child
      link="left_hip_pitch_link" />
    <axis
      xyz="0 1 0" />
    <limit
      lower="-1.2"
      upper="0.5"
      effort="130"
      velocity="13" />
  </joint>
  <link
    name="left_knee_link">
    <inertial>
      <origin
        xyz="-0.00759962 -0.00763316 -0.0876891"
        rpy="0 0 0" />
      <mass
        value="1.13156874" />
      <inertia
        ixx="0.00563088"
        ixy="-0.00011999"
        ixz="-0.0003535"
        iyy="0.00575105"
        iyz="-0.00015162"
        izz="0.00056885" />
    </inertial>

    <visual>
      <origin
        xyz="0 0 0"
        rpy="0 0 0" />
      <geometry>
        <mesh
          filename="../meshes/left_knee_link.STL" />
      </geometry>
      <material
        name="">
        <color
          rgba="1 1 1 1" />
      </material>
    </visual>
    <collision>
      <origin
        xyz="0 0 0"
        rpy="0 0 0" />
      <geometry>
        <mesh
          filename="../meshes/left_knee_link.STL" />
      </geometry>
    </collision>

    <collision>
      <origin xyz="-0.03 -0.04 -0.1" rpy="0 0 0" />
      <geometry>
        <cylinder radius="0.01" length="0.1"/>
      </geometry>
    </collision>

    <collision>
      <origin xyz="-0.03 -0.015 -0.25" rpy="0 0 0" />
      <geometry>
        <cylinder radius="0.01" length="0.1"/>
      </geometry>
    </collision>

    <collision>
      <origin xyz="-0.03 -0.0275 -0.175" rpy="0.3 0 0" />
      <geometry>
        <cylinder radius="0.01" length="0.05"/>
      </geometry>
    </collision>

  </link>
  <joint
    name="left_knee_joint"
    type="revolute">
    <origin
      xyz="0 0 -0.3"
      rpy="0 0 0" />
    <parent
      link="left_hip_pitch_link" />
    <child
      link="left_knee_link" />
    <axis
      xyz="0 1 0" />
    <limit
      lower="-0.5"
      upper="1.5"
      effort="130"
      velocity="13" />
  </joint>
  <link
    name="left_ankle_link">
    <inertial>
      <origin
        xyz="0.02790091 -0.0003417 -0.02643514"
        rpy="0 0 0" />
      <mass
        value="0.332" />
      <inertia
        ixx="8.94e-05"
        ixy="-7.21e-06"
        ixz="3.684e-05"
        iyy="0.00088173"
        iyz="9.9e-07"
        izz="0.00093571" />
    </inertial>
    <visual>
      <origin
        xyz="0 0 0"
        rpy="0 0 0" />
      <geometry>
        <mesh
          filename="../meshes/left_ankle_link.STL" />
      </geometry>
      <material
        name="">
        <color
          rgba="0.66667 0.69804 0.76863 1" />
      </material>
    </visual>
    <collision>
      <origin
        xyz="0 0 0"
        rpy="0 0 0" />
      <geometry>
        <mesh
          filename="../meshes/left_ankle_link.STL" />
      </geometry>
    </collision>
  </link>
  <joint
    name="left_ankle_joint"
    type="revolute">
    <origin
      xyz="0 0 -0.275"
      rpy="0 0 0" />
    <parent
      link="left_knee_link" />
    <child
      link="left_ankle_link" />
    <axis
      xyz="0 1 0" />
    <limit
      lower="-1.0"
      upper="1.0"
      effort="30"
      velocity="8.5" />
  </joint>
  <link
    name="right_hip_roll_link">
    <inertial>
      <origin
        xyz="0.06111611 -0.00136437 0.00062839"
        rpy="0 0 0" />
      <mass
        value="1.03840785" />
      <inertia
        ixx="0.0002943"
        ixy="-1.034e-05"
        ixz="-2.23e-06"
        iyy="0.00037778"
        iyz="-7.5e-07"
        izz="0.00050006" />
    </inertial>
    <visual>
      <origin
        xyz="0 0 0"
        rpy="0 0 0" />
      <geometry>
        <mesh
          filename="../meshes/right_hip_roll_link.STL" />
      </geometry>
      <material
        name="">
        <color
          rgba="1 1 1 1" />
      </material>
    </visual>
    <collision>
      <origin
        xyz="0 0 0"
        rpy="0 0 0" />
      <geometry>
        <mesh
          filename="../meshes/right_hip_roll_link.STL" />
      </geometry>
    </collision>
  </link>
  <joint
    name="right_hip_roll_joint"
    type="revolute">
    <origin
      xyz="-0.054984 -0.075 -0.042"
      rpy="0 0 0" />
    <parent
      link="pelvis" />
    <child
      link="right_hip_roll_link" />
    <axis
      xyz="1 0 0" />
    <limit
      lower="-1"
      upper="0.1"
      effort="80"
      velocity="15" />
  </joint>
  <link
    name="right_hip_yaw_link">


    <inertial>
      <origin
        xyz="0.0 0.01974414 -0.04022558"
        rpy="0 0 0" />
      <mass
        value="0.3035" />
      <inertia
        ixx="0.00045263"
        ixy="-0.0"
        ixz="-0.0"
        iyy="0.00045054"
        iyz="9.874e-05"
        izz="0.00016735" />
    </inertial>
    <visual>
      <origin
        xyz="0 0 0"
        rpy="0 0 0" />
      <geometry>
        <mesh
          filename="../meshes/right_hip_yaw_link.STL" />
      </geometry>
      <material
        name="">
        <color
          rgba="0.66667 0.69804 0.76863 1" />
      </material>
    </visual>
    <!-- <collision>
      <origin
        xyz="0 0 0"
        rpy="0 0 0" />
      <geometry>
        <mesh
          filename="../meshes/right_hip_yaw_link.STL" />
      </geometry>
    </collision> -->
  </link>
  <joint
    name="right_hip_yaw_joint"
    type="revolute">
    <origin
      xyz="0.065 0 -0.02725"
      rpy="0 0 0" />
    <parent
      link="right_hip_roll_link" />
    <child
      link="right_hip_yaw_link" />
    <axis
      xyz="0 0 1" />
    <limit
      lower="-0.7"
      upper="0.7"
      effort="80"
      velocity="15" />
  </joint>
  <link
    name="right_hip_pitch_link">
    <inertial>
      <origin
        xyz="-0.00072873 -0.00132281 -0.09181702"
        rpy="0 0 0" />
      <mass
        value="4.1691243" />
      <inertia
        ixx="0.03196599"
        ixy="0.00010019"
        ixz="-0.00042035"
        iyy="0.03363389"
        iyz="0.00064667"
        izz="0.0029827" />
    </inertial>
    <visual>
      <origin
        xyz="0 0 0"
        rpy="0 0 0" />
      <geometry>
        <mesh
          filename="../meshes/right_hip_pitch_link.STL" />
      </geometry>
      <material
        name="">
        <color
          rgba="0.79216 0.81961 0.93333 1" />
      </material>
    </visual>
    <collision>
      <origin
        xyz="0 0 0"
        rpy="0 0 0" />
      <geometry>
        <mesh
          filename="../meshes/right_hip_pitch_link.STL" />
      </geometry>
    </collision>
  </link>
  <joint
    name="right_hip_pitch_joint"
    type="revolute">
    <origin
      xyz="0 0 -0.082"
      rpy="0 0 0" />
    <parent
      link="right_hip_yaw_link" />
    <child
      link="right_hip_pitch_link" />
    <axis
      xyz="0 1 0" />
    <limit
      lower="-1.2"
      upper="0.5"
      effort="130"
      velocity="13" />
  </joint>
  <link
    name="right_knee_link">

    <inertial>
      <origin
        xyz="-0.00759465 0.00760875 -0.08797483"
        rpy="0 0 0" />
      <mass
        value="1.13133312" />
      <inertia
        ixx="0.00568577"
        ixy="0.00011869"
        ixz="-0.00036071"
        iyy="0.00580729"
        iyz="0.0001542"
        izz="0.0005665" />
    </inertial>
    <visual>
      <origin
        xyz="0 0 0"
        rpy="0 0 0" />
      <geometry>
        <mesh
          filename="../meshes/right_knee_link.STL" />
      </geometry>
      <material
        name="">
        <color
          rgba="1 1 1 1" />
      </material>
    </visual>
    <collision>
      <origin
        xyz="0 0 0"
        rpy="0 0 0" />
      <geometry>
        <mesh
          filename="../meshes/right_knee_link.STL" />
      </geometry>
    </collision>

    <collision>
      <origin xyz="-0.03 0.04 -0.1" rpy="0 0 0" />
      <geometry>
        <cylinder radius="0.01" length="0.1"/>
      </geometry>
    </collision>

    <collision>
      <origin xyz="-0.03 0.015 -0.25" rpy="0 0 0" />
      <geometry>
        <cylinder radius="0.01" length="0.1"/>
      </geometry>
    </collision>

    <collision>
      <origin xyz="-0.03 0.0275 -0.175" rpy="0.3 0 0" />
      <geometry>
        <cylinder radius="0.01" length="0.05"/>
      </geometry>
    </collision>


  </link>
  <joint
    name="right_knee_joint"
    type="revolute">
    <origin
      xyz="0 0 -0.3"
      rpy="0 0 0" />
    <parent
      link="right_hip_pitch_link" />
    <child
      link="right_knee_link" />
    <axis
      xyz="0 1 0" />
    <limit
      lower="-0.5"
      upper="1.5"
      effort="130"
      velocity="13" />
  </joint>
  <link
    name="right_ankle_link">
    <inertial>
      <origin
        xyz="0.02782273 0.00034253 -0.02643589"
        rpy="0 0 0" />
      <mass
        value="0.332" />
      <inertia
        ixx="8.939e-05"
        ixy="7.21e-06"
        ixz="3.674e-05"
        iyy="0.00088116"
        iyz="-9.9e-07"
        izz="0.00093514" />
    </inertial>
    <visual>
      <origin
        xyz="0 0 0"
        rpy="0 0 0" />
      <geometry>
        <mesh
          filename="../meshes/right_ankle_link.STL" />
      </geometry>
      <material
        name="">
        <color
          rgba="0.66667 0.69804 0.76863 1" />
      </material>
    </visual>
    <collision>
      <origin
        xyz="0 0 0"
        rpy="0 0 0" />
      <geometry>
        <mesh
          filename="../meshes/right_ankle_link.STL" />
      </geometry>
    </collision>
  </link>
  <joint
    name="right_ankle_joint"
    type="revolute">
    <origin
      xyz="0 0 -0.275"
      rpy="0 0 0" />
    <parent
      link="right_knee_link" />
    <child
      link="right_ankle_link" />
    <axis
      xyz="0 1 0" />
    <limit
      lower="-1.0"
      upper="1.0"
      effort="30"
      velocity="8.5" />
  </joint>
  <link
    name="torso_link">
    <inertial>
      <origin
        xyz="-0.01146002 -3.565e-05 -0.01353896"
        rpy="0 0 0" />
      <mass
        value="5.23559427" />
      <inertia
        ixx="0.05191432"
        ixy="-0.00028145"
        ixz="0.00140847"
        iyy="0.04533288"
        iyz="0.00021184"
        izz="0.02612206" />
    </inertial>
    <visual>
      <origin
        xyz="0 0 0"
        rpy="0 0 0" />
      <geometry>
        <mesh
          filename="../meshes/torso_link.STL" />
      </geometry>
      <material
        name="">
        <color
          rgba="0.66667 0.69804 0.76863 1" />
      </material>
    </visual>
    <collision>
      <origin
        xyz="0 0 0"
        rpy="0 0 0" />
      <geometry>
        <mesh
          filename="../meshes/torso_link.STL" />
      </geometry>
    </collision>
  </link>
  <joint
    name="torso_joint"
    type="fixed">
    <origin
      xyz="-0.00048373 -3.6691E-05 0.19483"
      rpy="0 0 0" />
    <parent
      link="pelvis" />
    <child
      link="torso_link" />
    <axis
      xyz="0 0 0" />
  </joint>
  <link
    name="left_shoulder_pitch_link">

    <inertial>
      <origin
        xyz="0.00867069 0.03737021 0.00758579"
        rpy="0 0 0" />
      <mass
        value="0.4278" />
      <inertia
        ixx="6.451e-05"
        ixy="5.33e-06"
        ixz="1.07e-06"
        iyy="5.53e-05"
        iyz="-5.34e-06"
        izz="8.025e-05" />
    </inertial>
    <visual>
      <origin
        xyz="0 0 0"
        rpy="0 0 0" />
      <geometry>
        <mesh
          filename="../meshes/left_shoulder_pitch_link.STL" />
      </geometry>
      <material
        name="">
        <color
          rgba="0.66667 0.69804 0.76863 1" />
      </material>
    </visual>
    <collision>
      <origin
        xyz="0 0 0"
        rpy="0 0 0" />
      <geometry>
        <mesh
          filename="../meshes/left_shoulder_pitch_link.STL" />
      </geometry>
    </collision>
  </link>
  <joint
    name="left_shoulder_pitch_joint"
    type="fixed">
    <origin
      xyz="0 0.12376 0.094735"
      rpy="0 0 0" />
    <parent
      link="torso_link" />
    <child
      link="left_shoulder_pitch_link" />
    <axis
      xyz="0 -0.98003 -0.19884" />
    <limit
      lower="-1"
      upper="1"
      effort="30"
      velocity="8.5" />
  </joint>
  <link
    name="left_shoulder_roll_link">


    <inertial>
      <origin
        xyz="0.00429054 0.02340453 -0.07603842"
        rpy="0 0 0" />
      <mass
        value="0.459" />
      <inertia
        ixx="0.00028072"
        ixy="1.286e-05"
        ixz="-0.00011072"
        iyy="0.00033308"
        iyz="2.792e-05"
        izz="0.00011561" />
    </inertial>
    <visual>
      <origin
        xyz="0 0 0"
        rpy="0 0 0" />
      <geometry>
        <mesh
          filename="../meshes/left_shoulder_roll_link.STL" />
      </geometry>
      <material
        name="">
        <color
          rgba="0.66667 0.69804 0.76863 1" />
      </material>
    </visual>
    <collision>
      <origin
        xyz="0 0 0"
        rpy="0 0 0" />
      <geometry>
        <mesh
          filename="../meshes/left_shoulder_roll_link.STL" />
      </geometry>
    </collision>
  </link>
  <joint
    name="left_shoulder_roll_joint"
    type="fixed">
    <origin
      xyz="0 0.039397 0.0079934"
      rpy="0 0 0" />
    <parent
      link="left_shoulder_pitch_link" />
    <child
      link="left_shoulder_roll_link" />
    <axis
      xyz="-1 0 0" />
    <limit
      lower="-1"
      upper="1"
      effort="30"
      velocity="8.5" />
  </joint>
  <link
    name="left_shoulder_yaw_link">

    <inertial>
      <origin
        xyz="-0.00099705 0.00435809 -0.0983263"
        rpy="0 0 0" />
      <mass
        value="0.59864616" />
      <inertia
        ixx="0.00108407"
        ixy="5.7e-07"
        ixz="-1.424e-05"
        iyy="0.00107053"
        iyz="6.191e-05"
        izz="0.00013883" />
    </inertial>
    <visual>
      <origin
        xyz="0 0 0"
        rpy="0 0 0" />
      <geometry>
        <mesh
          filename="../meshes/left_shoulder_yaw_link.STL" />
      </geometry>
      <material
        name="">
        <color
          rgba="0.66667 0.69804 0.76863 1" />
      </material>
    </visual>
    <collision>
      <origin
        xyz="0 0 0"
        rpy="0 0 0" />
      <geometry>
        <mesh
          filename="../meshes/left_shoulder_yaw_link.STL" />
      </geometry>
    </collision>
  </link>
  <joint
    name="left_shoulder_yaw_joint"
    type="fixed">
    <origin
      xyz="0 0.023977 -0.11053"
      rpy="0 0 0" />
    <parent
      link="left_shoulder_roll_link" />
    <child
      link="left_shoulder_yaw_link" />
    <axis
      xyz="0 0.0092635 0.99996" />
    <limit
      lower="-1"
      upper="1"
      effort="30"
      velocity="8.5" />
  </joint>
  <link
    name="left_elbow_link">
    <inertial>
      <origin
        xyz="2.92e-06 0.00688809 -0.09939661"
        rpy="0 0 0" />
      <mass
        value="0.127" />
      <inertia
        ixx="0.00074342"
        ixy="-0.0"
        ixz="-2e-08"
        iyy="0.00072358"
        iyz="-8.742e-05"
        izz="8.147e-05" />
    </inertial>
    <visual>
      <origin
        xyz="0 0 0"
        rpy="0 0 0" />
      <geometry>
        <mesh
          filename="../meshes/left_elbow_link.STL" />
      </geometry>
      <material
        name="">
        <color
          rgba="0.66667 0.69804 0.76863 1" />
      </material>
    </visual>
    <!-- <collision>
      <origin
        xyz="0 0 0"
        rpy="0 0 0" />
      <geometry>
        <mesh
          filename="../meshes/left_elbow_link.STL" />
      </geometry>
    </collision> -->
  </link>
  <joint
    name="left_elbow_joint"
    type="fixed">
    <origin
      xyz="0 -0.001132 -0.12219"
      rpy="0 0 0" />
    <parent
      link="left_shoulder_yaw_link" />
    <child
      link="left_elbow_link" />
    <axis
      xyz="0 -0.99996 0.0092635" />
    <limit
      lower="-1.5"
      upper="1.5"
      effort="30"
      velocity="8.5" />
  </joint>
  <link
    name="right_shoulder_pitch_link">


    <inertial>
      <origin
        xyz="0.00867069 -0.03737159 0.00758363"
        rpy="0 0 0" />
      <mass
        value="0.4278" />
      <inertia
        ixx="6.451e-05"
        ixy="-5.31e-06"
        ixz="1.1e-06"
        iyy="5.524e-05"
        iyz="5.31e-06"
        izz="8.031e-05" />
    </inertial>
    <visual>
      <origin
        xyz="0 0 0"
        rpy="0 0 0" />
      <geometry>
        <mesh
          filename="../meshes/right_shoulder_pitch_link.STL" />
      </geometry>
      <material
        name="">
        <color
          rgba="0.66667 0.69804 0.76863 1" />
      </material>
    </visual>
    <collision>
      <origin
        xyz="0 0 0"
        rpy="0 0 0" />
      <geometry>
        <mesh
          filename="../meshes/right_shoulder_pitch_link.STL" />
      </geometry>
    </collision>
  </link>
  <joint
    name="right_shoulder_pitch_joint"
    type="fixed">
    <origin
      xyz="0 -0.12358 0.094735"
      rpy="0 0 0" />
    <parent
      link="torso_link" />
    <child
      link="right_shoulder_pitch_link" />
    <axis
      xyz="0 0.98003 -0.19884" />
    <limit
      lower="-1"
      upper="1"
      effort="30"
      velocity="8.5" />
  </joint>
  <link
    name="right_shoulder_roll_link">


    <inertial>
      <origin
        xyz="0.00429169 -0.02340291 -0.07603682"
        rpy="0 0 0" />
      <mass
        value="0.459" />
      <inertia
        ixx="0.0002808"
        ixy="-1.285e-05"
        ixz="-0.00011076"
        iyy="0.00033317"
        iyz="-2.797e-05"
        izz="0.00011564" />
    </inertial>
    <visual>
      <origin
        xyz="0 0 0"
        rpy="0 0 0" />
      <geometry>
        <mesh
          filename="../meshes/right_shoulder_roll_link.STL" />
      </geometry>
      <material
        name="">
        <color
          rgba="0.66667 0.69804 0.76863 1" />
      </material>
    </visual>
    <collision>
      <origin
        xyz="0 0 0"
        rpy="0 0 0" />
      <geometry>
        <mesh
          filename="../meshes/right_shoulder_roll_link.STL" />
      </geometry>
    </collision>
  </link>
  <joint
    name="right_shoulder_roll_joint"
    type="fixed">
    <origin
      xyz="0 -0.039397 0.0079934"
      rpy="0 0 0" />
    <parent
      link="right_shoulder_pitch_link" />
    <child
      link="right_shoulder_roll_link" />
    <axis
      xyz="-1 0 0" />
    <limit
      lower="-1"
      upper="1"
      effort="30"
      velocity="8.5" />
  </joint>
  <link
    name="right_shoulder_yaw_link">


    <inertial>
      <origin
        xyz="-0.00101533 -0.0043536 -0.09834157"
        rpy="0 0 0" />
      <mass
        value="0.601" />
      <inertia
        ixx="0.00108567"
        ixy="-5.5e-07"
        ixz="-1.46e-05"
        iyy="0.00107209"
        iyz="-6.199e-05"
        izz="0.00014026" />
    </inertial>
    <visual>
      <origin
        xyz="0 0 0"
        rpy="0 0 0" />
      <geometry>
        <mesh
          filename="../meshes/right_shoulder_yaw_link.STL" />
      </geometry>
      <material
        name="">
        <color
          rgba="0.66667 0.69804 0.76863 1" />
      </material>
    </visual>
    <collision>
      <origin
        xyz="0 0 0"
        rpy="0 0 0" />
      <geometry>
        <mesh
          filename="../meshes/right_shoulder_yaw_link.STL" />
      </geometry>
    </collision>
  </link>
  <joint
    name="right_shoulder_yaw_joint"
    type="fixed">
    <origin
      xyz="0 -0.023977 -0.11053"
      rpy="0 0 0" />
    <parent
      link="right_shoulder_roll_link" />
    <child
      link="right_shoulder_yaw_link" />
    <axis
      xyz="0 -0.0092635 0.99996" />
    <limit
      lower="-1"
      upper="1"
      effort="30"
      velocity="8.5" />
  </joint>
  <link
    name="right_elbow_link">


    <inertial>
      <origin
        xyz="-2.92e-06 -0.00688809 -0.09939661"
        rpy="0 0 0" />
      <mass
        value="0.127" />
      <inertia
        ixx="0.00074342"
        ixy="-0.0"
        ixz="2e-08"
        iyy="0.00072358"
        iyz="8.742e-05"
        izz="8.147e-05" />
    </inertial>
    <visual>
      <origin
        xyz="0 0 0"
        rpy="0 0 0" />
      <geometry>
        <mesh
          filename="../meshes/right_elbow_link.STL" />
      </geometry>
      <material
        name="">
        <color
          rgba="0.66667 0.69804 0.76863 1" />
      </material>
    </visual>
    <!-- <collision>
      <origin
        xyz="0 0 0"
        rpy="0 0 0" />
      <geometry>
        <mesh
          filename="../meshes/right_elbow_link.STL" />
      </geometry>
    </collision> -->
  </link>
  <joint
    name="right_elbow_joint"
    type="fixed">
    <origin
      xyz="0 0.001132 -0.12219"
      rpy="0 0 0" />
    <parent
      link="right_shoulder_yaw_link" />
    <child
      link="right_elbow_link" />
    <axis
      xyz="0 0.99996 0.0092635" />
    <limit
      lower="-1.5"
      upper="1.5"
      effort="30"
      velocity="10" />
  </joint>
</robot>